[2022-09-17 07:12:57,726] {taskinstance.py:1032} INFO - Dependencies all met for <TaskInstance: green_taxi_data_v2.local_to_gcs_task scheduled__2019-03-02T06:00:00+00:00 [queued]>
[2022-09-17 07:12:57,739] {taskinstance.py:1032} INFO - Dependencies all met for <TaskInstance: green_taxi_data_v2.local_to_gcs_task scheduled__2019-03-02T06:00:00+00:00 [queued]>
[2022-09-17 07:12:57,739] {taskinstance.py:1238} INFO - 
--------------------------------------------------------------------------------
[2022-09-17 07:12:57,739] {taskinstance.py:1239} INFO - Starting attempt 1 of 2
[2022-09-17 07:12:57,739] {taskinstance.py:1240} INFO - 
--------------------------------------------------------------------------------
[2022-09-17 07:12:57,752] {taskinstance.py:1259} INFO - Executing <Task(PythonOperator): local_to_gcs_task> on 2019-03-02 06:00:00+00:00
[2022-09-17 07:12:57,761] {standard_task_runner.py:52} INFO - Started process 250 to run task
[2022-09-17 07:12:57,768] {standard_task_runner.py:76} INFO - Running: ['***', 'tasks', 'run', 'green_taxi_data_v2', 'local_to_gcs_task', 'scheduled__2019-03-02T06:00:00+00:00', '--job-id', '120', '--raw', '--subdir', 'DAGS_FOLDER/data_ingestion_gcs_dag.py', '--cfg-path', '/tmp/tmpjcjrx_mo', '--error-file', '/tmp/tmp4jmnttd9']
[2022-09-17 07:12:57,769] {standard_task_runner.py:77} INFO - Job 120: Subtask local_to_gcs_task
[2022-09-17 07:12:57,860] {logging_mixin.py:109} INFO - Running <TaskInstance: green_taxi_data_v2.local_to_gcs_task scheduled__2019-03-02T06:00:00+00:00 [running]> on host ea53df3427ed
[2022-09-17 07:12:57,933] {warnings.py:110} WARNING - /home/***/.local/lib/python3.7/site-packages/***/utils/context.py:152: AirflowContextDeprecationWarning: Accessing 'execution_date' from the template is deprecated and will be removed in a future version. Please use 'data_interval_start' or 'logical_date' instead.
  warnings.warn(_create_deprecation_warning(key, self._deprecation_replacements[key]))

[2022-09-17 07:12:57,974] {taskinstance.py:1426} INFO - Exporting the following env vars:
AIRFLOW_CTX_DAG_OWNER=***
AIRFLOW_CTX_DAG_ID=green_taxi_data_v2
AIRFLOW_CTX_TASK_ID=local_to_gcs_task
AIRFLOW_CTX_EXECUTION_DATE=2019-03-02T06:00:00+00:00
AIRFLOW_CTX_DAG_RUN_ID=scheduled__2019-03-02T06:00:00+00:00
[2022-09-17 07:12:59,692] {python.py:175} INFO - Done. Returned value was: None
[2022-09-17 07:12:59,705] {taskinstance.py:1277} INFO - Marking task as SUCCESS. dag_id=green_taxi_data_v2, task_id=local_to_gcs_task, execution_date=20190302T060000, start_date=20220917T071257, end_date=20220917T071259
[2022-09-17 07:12:59,761] {local_task_job.py:154} INFO - Task exited with return code 0
[2022-09-17 07:12:59,812] {local_task_job.py:264} INFO - 1 downstream tasks scheduled from follow-on schedule check
[2022-09-20 15:11:51,815] {taskinstance.py:1032} INFO - Dependencies all met for <TaskInstance: green_taxi_data_v2.local_to_gcs_task scheduled__2019-03-02T06:00:00+00:00 [queued]>
[2022-09-20 15:11:51,835] {taskinstance.py:1032} INFO - Dependencies all met for <TaskInstance: green_taxi_data_v2.local_to_gcs_task scheduled__2019-03-02T06:00:00+00:00 [queued]>
[2022-09-20 15:11:51,836] {taskinstance.py:1238} INFO - 
--------------------------------------------------------------------------------
[2022-09-20 15:11:51,836] {taskinstance.py:1239} INFO - Starting attempt 1 of 2
[2022-09-20 15:11:51,836] {taskinstance.py:1240} INFO - 
--------------------------------------------------------------------------------
[2022-09-20 15:11:51,860] {taskinstance.py:1259} INFO - Executing <Task(PythonOperator): local_to_gcs_task> on 2019-03-02 06:00:00+00:00
[2022-09-20 15:11:51,869] {standard_task_runner.py:52} INFO - Started process 138 to run task
[2022-09-20 15:11:51,876] {standard_task_runner.py:76} INFO - Running: ['***', 'tasks', 'run', 'green_taxi_data_v2', 'local_to_gcs_task', 'scheduled__2019-03-02T06:00:00+00:00', '--job-id', '40', '--raw', '--subdir', 'DAGS_FOLDER/data_ingestion_gcs_dag.py', '--cfg-path', '/tmp/tmpsa42wby2', '--error-file', '/tmp/tmpmegsqqpn']
[2022-09-20 15:11:51,878] {standard_task_runner.py:77} INFO - Job 40: Subtask local_to_gcs_task
[2022-09-20 15:11:51,970] {logging_mixin.py:109} INFO - Running <TaskInstance: green_taxi_data_v2.local_to_gcs_task scheduled__2019-03-02T06:00:00+00:00 [running]> on host 0a2e8243e3d8
[2022-09-20 15:11:52,060] {warnings.py:110} WARNING - /home/***/.local/lib/python3.7/site-packages/***/utils/context.py:152: AirflowContextDeprecationWarning: Accessing 'execution_date' from the template is deprecated and will be removed in a future version. Please use 'data_interval_start' or 'logical_date' instead.
  warnings.warn(_create_deprecation_warning(key, self._deprecation_replacements[key]))

[2022-09-20 15:11:52,152] {taskinstance.py:1426} INFO - Exporting the following env vars:
AIRFLOW_CTX_DAG_OWNER=***
AIRFLOW_CTX_DAG_ID=green_taxi_data_v2
AIRFLOW_CTX_TASK_ID=local_to_gcs_task
AIRFLOW_CTX_EXECUTION_DATE=2019-03-02T06:00:00+00:00
AIRFLOW_CTX_DAG_RUN_ID=scheduled__2019-03-02T06:00:00+00:00
[2022-09-20 15:11:53,185] {taskinstance.py:1700} ERROR - Task failed with exception
Traceback (most recent call last):
  File "/home/airflow/.local/lib/python3.7/site-packages/google/cloud/storage/blob.py", line 2594, in upload_from_file
    retry=retry,
  File "/home/airflow/.local/lib/python3.7/site-packages/google/cloud/storage/blob.py", line 2412, in _do_upload
    retry=retry,
  File "/home/airflow/.local/lib/python3.7/site-packages/google/cloud/storage/blob.py", line 2237, in _do_resumable_upload
    retry=retry,
  File "/home/airflow/.local/lib/python3.7/site-packages/google/cloud/storage/blob.py", line 2112, in _initiate_resumable_upload
    timeout=timeout,
  File "/home/airflow/.local/lib/python3.7/site-packages/google/resumable_media/requests/upload.py", line 421, in initiate
    retriable_request, self._get_status_code, self._retry_strategy
  File "/home/airflow/.local/lib/python3.7/site-packages/google/resumable_media/requests/_request_helpers.py", line 147, in wait_and_retry
    response = func()
  File "/home/airflow/.local/lib/python3.7/site-packages/google/resumable_media/requests/upload.py", line 416, in retriable_request
    self._process_initiate_response(result)
  File "/home/airflow/.local/lib/python3.7/site-packages/google/resumable_media/_upload.py", line 503, in _process_initiate_response
    callback=self._make_invalid,
  File "/home/airflow/.local/lib/python3.7/site-packages/google/resumable_media/_helpers.py", line 104, in require_status_code
    *status_codes
google.resumable_media.common.InvalidResponse: ('Request failed with status code', 404, 'Expected one of', <HTTPStatus.OK: 200>, <HTTPStatus.CREATED: 201>)

During handling of the above exception, another exception occurred:

Traceback (most recent call last):
  File "/home/airflow/.local/lib/python3.7/site-packages/airflow/models/taskinstance.py", line 1329, in _run_raw_task
    self._execute_task_with_callbacks(context)
  File "/home/airflow/.local/lib/python3.7/site-packages/airflow/models/taskinstance.py", line 1455, in _execute_task_with_callbacks
    result = self._execute_task(context, self.task)
  File "/home/airflow/.local/lib/python3.7/site-packages/airflow/models/taskinstance.py", line 1511, in _execute_task
    result = execute_callable(context=context)
  File "/home/airflow/.local/lib/python3.7/site-packages/airflow/operators/python.py", line 174, in execute
    return_value = self.execute_callable()
  File "/home/airflow/.local/lib/python3.7/site-packages/airflow/operators/python.py", line 185, in execute_callable
    return self.python_callable(*self.op_args, **self.op_kwargs)
  File "/opt/airflow/dags/data_ingestion_gcs_dag.py", line 29, in upload_to_gcs
    blob.upload_from_filename(local_file)
  File "/home/airflow/.local/lib/python3.7/site-packages/google/cloud/storage/blob.py", line 2735, in upload_from_filename
    retry=retry,
  File "/home/airflow/.local/lib/python3.7/site-packages/google/cloud/storage/blob.py", line 2598, in upload_from_file
    _raise_from_invalid_response(exc)
  File "/home/airflow/.local/lib/python3.7/site-packages/google/cloud/storage/blob.py", line 4466, in _raise_from_invalid_response
    raise exceptions.from_http_status(response.status_code, message, response=response)
google.api_core.exceptions.NotFound: 404 POST https://storage.googleapis.com/upload/storage/v1/b/tez-bucket-new/o?uploadType=resumable: {
  "error": {
    "code": 404,
    "message": "The specified bucket does not exist.",
    "errors": [
      {
        "message": "The specified bucket does not exist.",
        "domain": "global",
        "reason": "notFound"
      }
    ]
  }
}
: ('Request failed with status code', 404, 'Expected one of', <HTTPStatus.OK: 200>, <HTTPStatus.CREATED: 201>)
[2022-09-20 15:11:53,206] {taskinstance.py:1277} INFO - Marking task as UP_FOR_RETRY. dag_id=green_taxi_data_v2, task_id=local_to_gcs_task, execution_date=20190302T060000, start_date=20220920T151151, end_date=20220920T151153
[2022-09-20 15:11:53,226] {standard_task_runner.py:92} ERROR - Failed to execute job 40 for task local_to_gcs_task
Traceback (most recent call last):
  File "/home/airflow/.local/lib/python3.7/site-packages/google/cloud/storage/blob.py", line 2594, in upload_from_file
    retry=retry,
  File "/home/airflow/.local/lib/python3.7/site-packages/google/cloud/storage/blob.py", line 2412, in _do_upload
    retry=retry,
  File "/home/airflow/.local/lib/python3.7/site-packages/google/cloud/storage/blob.py", line 2237, in _do_resumable_upload
    retry=retry,
  File "/home/airflow/.local/lib/python3.7/site-packages/google/cloud/storage/blob.py", line 2112, in _initiate_resumable_upload
    timeout=timeout,
  File "/home/airflow/.local/lib/python3.7/site-packages/google/resumable_media/requests/upload.py", line 421, in initiate
    retriable_request, self._get_status_code, self._retry_strategy
  File "/home/airflow/.local/lib/python3.7/site-packages/google/resumable_media/requests/_request_helpers.py", line 147, in wait_and_retry
    response = func()
  File "/home/airflow/.local/lib/python3.7/site-packages/google/resumable_media/requests/upload.py", line 416, in retriable_request
    self._process_initiate_response(result)
  File "/home/airflow/.local/lib/python3.7/site-packages/google/resumable_media/_upload.py", line 503, in _process_initiate_response
    callback=self._make_invalid,
  File "/home/airflow/.local/lib/python3.7/site-packages/google/resumable_media/_helpers.py", line 104, in require_status_code
    *status_codes
google.resumable_media.common.InvalidResponse: ('Request failed with status code', 404, 'Expected one of', <HTTPStatus.OK: 200>, <HTTPStatus.CREATED: 201>)

During handling of the above exception, another exception occurred:

Traceback (most recent call last):
  File "/home/airflow/.local/lib/python3.7/site-packages/airflow/task/task_runner/standard_task_runner.py", line 85, in _start_by_fork
    args.func(args, dag=self.dag)
  File "/home/airflow/.local/lib/python3.7/site-packages/airflow/cli/cli_parser.py", line 48, in command
    return func(*args, **kwargs)
  File "/home/airflow/.local/lib/python3.7/site-packages/airflow/utils/cli.py", line 92, in wrapper
    return f(*args, **kwargs)
  File "/home/airflow/.local/lib/python3.7/site-packages/airflow/cli/commands/task_command.py", line 298, in task_run
    _run_task_by_selected_method(args, dag, ti)
  File "/home/airflow/.local/lib/python3.7/site-packages/airflow/cli/commands/task_command.py", line 107, in _run_task_by_selected_method
    _run_raw_task(args, ti)
  File "/home/airflow/.local/lib/python3.7/site-packages/airflow/cli/commands/task_command.py", line 184, in _run_raw_task
    error_file=args.error_file,
  File "/home/airflow/.local/lib/python3.7/site-packages/airflow/utils/session.py", line 70, in wrapper
    return func(*args, session=session, **kwargs)
  File "/home/airflow/.local/lib/python3.7/site-packages/airflow/models/taskinstance.py", line 1329, in _run_raw_task
    self._execute_task_with_callbacks(context)
  File "/home/airflow/.local/lib/python3.7/site-packages/airflow/models/taskinstance.py", line 1455, in _execute_task_with_callbacks
    result = self._execute_task(context, self.task)
  File "/home/airflow/.local/lib/python3.7/site-packages/airflow/models/taskinstance.py", line 1511, in _execute_task
    result = execute_callable(context=context)
  File "/home/airflow/.local/lib/python3.7/site-packages/airflow/operators/python.py", line 174, in execute
    return_value = self.execute_callable()
  File "/home/airflow/.local/lib/python3.7/site-packages/airflow/operators/python.py", line 185, in execute_callable
    return self.python_callable(*self.op_args, **self.op_kwargs)
  File "/opt/airflow/dags/data_ingestion_gcs_dag.py", line 29, in upload_to_gcs
    blob.upload_from_filename(local_file)
  File "/home/airflow/.local/lib/python3.7/site-packages/google/cloud/storage/blob.py", line 2735, in upload_from_filename
    retry=retry,
  File "/home/airflow/.local/lib/python3.7/site-packages/google/cloud/storage/blob.py", line 2598, in upload_from_file
    _raise_from_invalid_response(exc)
  File "/home/airflow/.local/lib/python3.7/site-packages/google/cloud/storage/blob.py", line 4466, in _raise_from_invalid_response
    raise exceptions.from_http_status(response.status_code, message, response=response)
google.api_core.exceptions.NotFound: 404 POST https://storage.googleapis.com/upload/storage/v1/b/tez-bucket-new/o?uploadType=resumable: {
  "error": {
    "code": 404,
    "message": "The specified bucket does not exist.",
    "errors": [
      {
        "message": "The specified bucket does not exist.",
        "domain": "global",
        "reason": "notFound"
      }
    ]
  }
}
: ('Request failed with status code', 404, 'Expected one of', <HTTPStatus.OK: 200>, <HTTPStatus.CREATED: 201>)
[2022-09-20 15:11:53,258] {local_task_job.py:154} INFO - Task exited with return code 1
[2022-09-20 15:11:53,305] {local_task_job.py:264} INFO - 0 downstream tasks scheduled from follow-on schedule check
[2022-09-20 15:31:43,103] {taskinstance.py:1032} INFO - Dependencies all met for <TaskInstance: green_taxi_data_v2.local_to_gcs_task scheduled__2019-03-02T06:00:00+00:00 [queued]>
[2022-09-20 15:31:43,131] {taskinstance.py:1032} INFO - Dependencies all met for <TaskInstance: green_taxi_data_v2.local_to_gcs_task scheduled__2019-03-02T06:00:00+00:00 [queued]>
[2022-09-20 15:31:43,131] {taskinstance.py:1238} INFO - 
--------------------------------------------------------------------------------
[2022-09-20 15:31:43,131] {taskinstance.py:1239} INFO - Starting attempt 1 of 2
[2022-09-20 15:31:43,131] {taskinstance.py:1240} INFO - 
--------------------------------------------------------------------------------
[2022-09-20 15:31:43,150] {taskinstance.py:1259} INFO - Executing <Task(PythonOperator): local_to_gcs_task> on 2019-03-02 06:00:00+00:00
[2022-09-20 15:31:43,159] {standard_task_runner.py:52} INFO - Started process 264 to run task
[2022-09-20 15:31:43,186] {standard_task_runner.py:76} INFO - Running: ['***', 'tasks', 'run', 'green_taxi_data_v2', 'local_to_gcs_task', 'scheduled__2019-03-02T06:00:00+00:00', '--job-id', '28', '--raw', '--subdir', 'DAGS_FOLDER/data_ingestion_gcs_dag.py', '--cfg-path', '/tmp/tmpuakifbz5', '--error-file', '/tmp/tmps_u_8o15']
[2022-09-20 15:31:43,194] {standard_task_runner.py:77} INFO - Job 28: Subtask local_to_gcs_task
[2022-09-20 15:31:43,358] {logging_mixin.py:109} INFO - Running <TaskInstance: green_taxi_data_v2.local_to_gcs_task scheduled__2019-03-02T06:00:00+00:00 [running]> on host 788dccad41b9
[2022-09-20 15:31:43,469] {warnings.py:110} WARNING - /home/***/.local/lib/python3.7/site-packages/***/utils/context.py:152: AirflowContextDeprecationWarning: Accessing 'execution_date' from the template is deprecated and will be removed in a future version. Please use 'data_interval_start' or 'logical_date' instead.
  warnings.warn(_create_deprecation_warning(key, self._deprecation_replacements[key]))

[2022-09-20 15:31:43,531] {taskinstance.py:1426} INFO - Exporting the following env vars:
AIRFLOW_CTX_DAG_OWNER=***
AIRFLOW_CTX_DAG_ID=green_taxi_data_v2
AIRFLOW_CTX_TASK_ID=local_to_gcs_task
AIRFLOW_CTX_EXECUTION_DATE=2019-03-02T06:00:00+00:00
AIRFLOW_CTX_DAG_RUN_ID=scheduled__2019-03-02T06:00:00+00:00
[2022-09-20 15:31:44,313] {python.py:175} INFO - Done. Returned value was: None
[2022-09-20 15:31:44,559] {taskinstance.py:1277} INFO - Marking task as SUCCESS. dag_id=green_taxi_data_v2, task_id=local_to_gcs_task, execution_date=20190302T060000, start_date=20220920T153143, end_date=20220920T153144
[2022-09-20 15:31:44,672] {local_task_job.py:154} INFO - Task exited with return code 0
[2022-09-20 15:31:44,784] {local_task_job.py:264} INFO - 1 downstream tasks scheduled from follow-on schedule check
