[2022-09-17 06:52:07,339] {taskinstance.py:1032} INFO - Dependencies all met for <TaskInstance: fhv_data_v2.local_to_gcs_task scheduled__2019-04-02T06:00:00+00:00 [queued]>
[2022-09-17 06:52:07,353] {taskinstance.py:1032} INFO - Dependencies all met for <TaskInstance: fhv_data_v2.local_to_gcs_task scheduled__2019-04-02T06:00:00+00:00 [queued]>
[2022-09-17 06:52:07,353] {taskinstance.py:1238} INFO - 
--------------------------------------------------------------------------------
[2022-09-17 06:52:07,353] {taskinstance.py:1239} INFO - Starting attempt 1 of 2
[2022-09-17 06:52:07,353] {taskinstance.py:1240} INFO - 
--------------------------------------------------------------------------------
[2022-09-17 06:52:07,366] {taskinstance.py:1259} INFO - Executing <Task(PythonOperator): local_to_gcs_task> on 2019-04-02 06:00:00+00:00
[2022-09-17 06:52:07,374] {standard_task_runner.py:52} INFO - Started process 7376 to run task
[2022-09-17 06:52:07,378] {standard_task_runner.py:76} INFO - Running: ['***', 'tasks', 'run', 'fhv_data_v2', 'local_to_gcs_task', 'scheduled__2019-04-02T06:00:00+00:00', '--job-id', '88', '--raw', '--subdir', 'DAGS_FOLDER/data_ingestion_gcs_dag.py', '--cfg-path', '/tmp/tmpifkp8j_r', '--error-file', '/tmp/tmpxylpzpnz']
[2022-09-17 06:52:07,379] {standard_task_runner.py:77} INFO - Job 88: Subtask local_to_gcs_task
[2022-09-17 06:52:07,454] {logging_mixin.py:109} INFO - Running <TaskInstance: fhv_data_v2.local_to_gcs_task scheduled__2019-04-02T06:00:00+00:00 [running]> on host 10d063af5ba7
[2022-09-17 06:52:07,504] {warnings.py:110} WARNING - /home/***/.local/lib/python3.7/site-packages/***/utils/context.py:152: AirflowContextDeprecationWarning: Accessing 'execution_date' from the template is deprecated and will be removed in a future version. Please use 'data_interval_start' or 'logical_date' instead.
  warnings.warn(_create_deprecation_warning(key, self._deprecation_replacements[key]))

[2022-09-17 06:52:07,536] {taskinstance.py:1426} INFO - Exporting the following env vars:
AIRFLOW_CTX_DAG_OWNER=***
AIRFLOW_CTX_DAG_ID=fhv_data_v2
AIRFLOW_CTX_TASK_ID=local_to_gcs_task
AIRFLOW_CTX_EXECUTION_DATE=2019-04-02T06:00:00+00:00
AIRFLOW_CTX_DAG_RUN_ID=scheduled__2019-04-02T06:00:00+00:00
[2022-09-17 06:52:09,029] {python.py:175} INFO - Done. Returned value was: None
[2022-09-17 06:52:09,046] {taskinstance.py:1277} INFO - Marking task as SUCCESS. dag_id=fhv_data_v2, task_id=local_to_gcs_task, execution_date=20190402T060000, start_date=20220917T065207, end_date=20220917T065209
[2022-09-17 06:52:09,126] {local_task_job.py:154} INFO - Task exited with return code 0
[2022-09-17 06:52:09,253] {local_task_job.py:264} INFO - 1 downstream tasks scheduled from follow-on schedule check
[2022-09-20 15:11:50,677] {taskinstance.py:1032} INFO - Dependencies all met for <TaskInstance: fhv_data_v2.local_to_gcs_task scheduled__2019-04-02T06:00:00+00:00 [queued]>
[2022-09-20 15:11:50,700] {taskinstance.py:1032} INFO - Dependencies all met for <TaskInstance: fhv_data_v2.local_to_gcs_task scheduled__2019-04-02T06:00:00+00:00 [queued]>
[2022-09-20 15:11:50,700] {taskinstance.py:1238} INFO - 
--------------------------------------------------------------------------------
[2022-09-20 15:11:50,700] {taskinstance.py:1239} INFO - Starting attempt 1 of 2
[2022-09-20 15:11:50,700] {taskinstance.py:1240} INFO - 
--------------------------------------------------------------------------------
[2022-09-20 15:11:50,722] {taskinstance.py:1259} INFO - Executing <Task(PythonOperator): local_to_gcs_task> on 2019-04-02 06:00:00+00:00
[2022-09-20 15:11:50,733] {standard_task_runner.py:52} INFO - Started process 135 to run task
[2022-09-20 15:11:50,750] {standard_task_runner.py:76} INFO - Running: ['***', 'tasks', 'run', 'fhv_data_v2', 'local_to_gcs_task', 'scheduled__2019-04-02T06:00:00+00:00', '--job-id', '37', '--raw', '--subdir', 'DAGS_FOLDER/data_ingestion_gcs_dag.py', '--cfg-path', '/tmp/tmpsmk1yd5z', '--error-file', '/tmp/tmp3eb_7dsn']
[2022-09-20 15:11:50,752] {standard_task_runner.py:77} INFO - Job 37: Subtask local_to_gcs_task
[2022-09-20 15:11:50,903] {logging_mixin.py:109} INFO - Running <TaskInstance: fhv_data_v2.local_to_gcs_task scheduled__2019-04-02T06:00:00+00:00 [running]> on host 0a2e8243e3d8
[2022-09-20 15:11:51,142] {warnings.py:110} WARNING - /home/***/.local/lib/python3.7/site-packages/***/utils/context.py:152: AirflowContextDeprecationWarning: Accessing 'execution_date' from the template is deprecated and will be removed in a future version. Please use 'data_interval_start' or 'logical_date' instead.
  warnings.warn(_create_deprecation_warning(key, self._deprecation_replacements[key]))

[2022-09-20 15:11:51,279] {taskinstance.py:1426} INFO - Exporting the following env vars:
AIRFLOW_CTX_DAG_OWNER=***
AIRFLOW_CTX_DAG_ID=fhv_data_v2
AIRFLOW_CTX_TASK_ID=local_to_gcs_task
AIRFLOW_CTX_EXECUTION_DATE=2019-04-02T06:00:00+00:00
AIRFLOW_CTX_DAG_RUN_ID=scheduled__2019-04-02T06:00:00+00:00
[2022-09-20 15:11:51,928] {taskinstance.py:1700} ERROR - Task failed with exception
Traceback (most recent call last):
  File "/home/airflow/.local/lib/python3.7/site-packages/google/cloud/storage/blob.py", line 2594, in upload_from_file
    retry=retry,
  File "/home/airflow/.local/lib/python3.7/site-packages/google/cloud/storage/blob.py", line 2412, in _do_upload
    retry=retry,
  File "/home/airflow/.local/lib/python3.7/site-packages/google/cloud/storage/blob.py", line 2237, in _do_resumable_upload
    retry=retry,
  File "/home/airflow/.local/lib/python3.7/site-packages/google/cloud/storage/blob.py", line 2112, in _initiate_resumable_upload
    timeout=timeout,
  File "/home/airflow/.local/lib/python3.7/site-packages/google/resumable_media/requests/upload.py", line 421, in initiate
    retriable_request, self._get_status_code, self._retry_strategy
  File "/home/airflow/.local/lib/python3.7/site-packages/google/resumable_media/requests/_request_helpers.py", line 147, in wait_and_retry
    response = func()
  File "/home/airflow/.local/lib/python3.7/site-packages/google/resumable_media/requests/upload.py", line 416, in retriable_request
    self._process_initiate_response(result)
  File "/home/airflow/.local/lib/python3.7/site-packages/google/resumable_media/_upload.py", line 503, in _process_initiate_response
    callback=self._make_invalid,
  File "/home/airflow/.local/lib/python3.7/site-packages/google/resumable_media/_helpers.py", line 104, in require_status_code
    *status_codes
google.resumable_media.common.InvalidResponse: ('Request failed with status code', 404, 'Expected one of', <HTTPStatus.OK: 200>, <HTTPStatus.CREATED: 201>)

During handling of the above exception, another exception occurred:

Traceback (most recent call last):
  File "/home/airflow/.local/lib/python3.7/site-packages/airflow/models/taskinstance.py", line 1329, in _run_raw_task
    self._execute_task_with_callbacks(context)
  File "/home/airflow/.local/lib/python3.7/site-packages/airflow/models/taskinstance.py", line 1455, in _execute_task_with_callbacks
    result = self._execute_task(context, self.task)
  File "/home/airflow/.local/lib/python3.7/site-packages/airflow/models/taskinstance.py", line 1511, in _execute_task
    result = execute_callable(context=context)
  File "/home/airflow/.local/lib/python3.7/site-packages/airflow/operators/python.py", line 174, in execute
    return_value = self.execute_callable()
  File "/home/airflow/.local/lib/python3.7/site-packages/airflow/operators/python.py", line 185, in execute_callable
    return self.python_callable(*self.op_args, **self.op_kwargs)
  File "/opt/airflow/dags/data_ingestion_gcs_dag.py", line 29, in upload_to_gcs
    blob.upload_from_filename(local_file)
  File "/home/airflow/.local/lib/python3.7/site-packages/google/cloud/storage/blob.py", line 2735, in upload_from_filename
    retry=retry,
  File "/home/airflow/.local/lib/python3.7/site-packages/google/cloud/storage/blob.py", line 2598, in upload_from_file
    _raise_from_invalid_response(exc)
  File "/home/airflow/.local/lib/python3.7/site-packages/google/cloud/storage/blob.py", line 4466, in _raise_from_invalid_response
    raise exceptions.from_http_status(response.status_code, message, response=response)
google.api_core.exceptions.NotFound: 404 POST https://storage.googleapis.com/upload/storage/v1/b/tez-bucket-new/o?uploadType=resumable: {
  "error": {
    "code": 404,
    "message": "The specified bucket does not exist.",
    "errors": [
      {
        "message": "The specified bucket does not exist.",
        "domain": "global",
        "reason": "notFound"
      }
    ]
  }
}
: ('Request failed with status code', 404, 'Expected one of', <HTTPStatus.OK: 200>, <HTTPStatus.CREATED: 201>)
[2022-09-20 15:11:51,963] {taskinstance.py:1277} INFO - Marking task as UP_FOR_RETRY. dag_id=fhv_data_v2, task_id=local_to_gcs_task, execution_date=20190402T060000, start_date=20220920T151150, end_date=20220920T151151
[2022-09-20 15:11:51,995] {standard_task_runner.py:92} ERROR - Failed to execute job 37 for task local_to_gcs_task
Traceback (most recent call last):
  File "/home/airflow/.local/lib/python3.7/site-packages/google/cloud/storage/blob.py", line 2594, in upload_from_file
    retry=retry,
  File "/home/airflow/.local/lib/python3.7/site-packages/google/cloud/storage/blob.py", line 2412, in _do_upload
    retry=retry,
  File "/home/airflow/.local/lib/python3.7/site-packages/google/cloud/storage/blob.py", line 2237, in _do_resumable_upload
    retry=retry,
  File "/home/airflow/.local/lib/python3.7/site-packages/google/cloud/storage/blob.py", line 2112, in _initiate_resumable_upload
    timeout=timeout,
  File "/home/airflow/.local/lib/python3.7/site-packages/google/resumable_media/requests/upload.py", line 421, in initiate
    retriable_request, self._get_status_code, self._retry_strategy
  File "/home/airflow/.local/lib/python3.7/site-packages/google/resumable_media/requests/_request_helpers.py", line 147, in wait_and_retry
    response = func()
  File "/home/airflow/.local/lib/python3.7/site-packages/google/resumable_media/requests/upload.py", line 416, in retriable_request
    self._process_initiate_response(result)
  File "/home/airflow/.local/lib/python3.7/site-packages/google/resumable_media/_upload.py", line 503, in _process_initiate_response
    callback=self._make_invalid,
  File "/home/airflow/.local/lib/python3.7/site-packages/google/resumable_media/_helpers.py", line 104, in require_status_code
    *status_codes
google.resumable_media.common.InvalidResponse: ('Request failed with status code', 404, 'Expected one of', <HTTPStatus.OK: 200>, <HTTPStatus.CREATED: 201>)

During handling of the above exception, another exception occurred:

Traceback (most recent call last):
  File "/home/airflow/.local/lib/python3.7/site-packages/airflow/task/task_runner/standard_task_runner.py", line 85, in _start_by_fork
    args.func(args, dag=self.dag)
  File "/home/airflow/.local/lib/python3.7/site-packages/airflow/cli/cli_parser.py", line 48, in command
    return func(*args, **kwargs)
  File "/home/airflow/.local/lib/python3.7/site-packages/airflow/utils/cli.py", line 92, in wrapper
    return f(*args, **kwargs)
  File "/home/airflow/.local/lib/python3.7/site-packages/airflow/cli/commands/task_command.py", line 298, in task_run
    _run_task_by_selected_method(args, dag, ti)
  File "/home/airflow/.local/lib/python3.7/site-packages/airflow/cli/commands/task_command.py", line 107, in _run_task_by_selected_method
    _run_raw_task(args, ti)
  File "/home/airflow/.local/lib/python3.7/site-packages/airflow/cli/commands/task_command.py", line 184, in _run_raw_task
    error_file=args.error_file,
  File "/home/airflow/.local/lib/python3.7/site-packages/airflow/utils/session.py", line 70, in wrapper
    return func(*args, session=session, **kwargs)
  File "/home/airflow/.local/lib/python3.7/site-packages/airflow/models/taskinstance.py", line 1329, in _run_raw_task
    self._execute_task_with_callbacks(context)
  File "/home/airflow/.local/lib/python3.7/site-packages/airflow/models/taskinstance.py", line 1455, in _execute_task_with_callbacks
    result = self._execute_task(context, self.task)
  File "/home/airflow/.local/lib/python3.7/site-packages/airflow/models/taskinstance.py", line 1511, in _execute_task
    result = execute_callable(context=context)
  File "/home/airflow/.local/lib/python3.7/site-packages/airflow/operators/python.py", line 174, in execute
    return_value = self.execute_callable()
  File "/home/airflow/.local/lib/python3.7/site-packages/airflow/operators/python.py", line 185, in execute_callable
    return self.python_callable(*self.op_args, **self.op_kwargs)
  File "/opt/airflow/dags/data_ingestion_gcs_dag.py", line 29, in upload_to_gcs
    blob.upload_from_filename(local_file)
  File "/home/airflow/.local/lib/python3.7/site-packages/google/cloud/storage/blob.py", line 2735, in upload_from_filename
    retry=retry,
  File "/home/airflow/.local/lib/python3.7/site-packages/google/cloud/storage/blob.py", line 2598, in upload_from_file
    _raise_from_invalid_response(exc)
  File "/home/airflow/.local/lib/python3.7/site-packages/google/cloud/storage/blob.py", line 4466, in _raise_from_invalid_response
    raise exceptions.from_http_status(response.status_code, message, response=response)
google.api_core.exceptions.NotFound: 404 POST https://storage.googleapis.com/upload/storage/v1/b/tez-bucket-new/o?uploadType=resumable: {
  "error": {
    "code": 404,
    "message": "The specified bucket does not exist.",
    "errors": [
      {
        "message": "The specified bucket does not exist.",
        "domain": "global",
        "reason": "notFound"
      }
    ]
  }
}
: ('Request failed with status code', 404, 'Expected one of', <HTTPStatus.OK: 200>, <HTTPStatus.CREATED: 201>)
[2022-09-20 15:11:52,061] {local_task_job.py:154} INFO - Task exited with return code 1
[2022-09-20 15:11:52,183] {local_task_job.py:264} INFO - 0 downstream tasks scheduled from follow-on schedule check
[2022-09-20 15:19:00,604] {taskinstance.py:1032} INFO - Dependencies all met for <TaskInstance: fhv_data_v2.local_to_gcs_task scheduled__2019-04-02T06:00:00+00:00 [queued]>
[2022-09-20 15:19:00,618] {taskinstance.py:1032} INFO - Dependencies all met for <TaskInstance: fhv_data_v2.local_to_gcs_task scheduled__2019-04-02T06:00:00+00:00 [queued]>
[2022-09-20 15:19:00,618] {taskinstance.py:1238} INFO - 
--------------------------------------------------------------------------------
[2022-09-20 15:19:00,618] {taskinstance.py:1239} INFO - Starting attempt 1 of 2
[2022-09-20 15:19:00,619] {taskinstance.py:1240} INFO - 
--------------------------------------------------------------------------------
[2022-09-20 15:19:00,634] {taskinstance.py:1259} INFO - Executing <Task(PythonOperator): local_to_gcs_task> on 2019-04-02 06:00:00+00:00
[2022-09-20 15:19:00,641] {standard_task_runner.py:52} INFO - Started process 519 to run task
[2022-09-20 15:19:00,647] {standard_task_runner.py:76} INFO - Running: ['***', 'tasks', 'run', 'fhv_data_v2', 'local_to_gcs_task', 'scheduled__2019-04-02T06:00:00+00:00', '--job-id', '56', '--raw', '--subdir', 'DAGS_FOLDER/data_ingestion_gcs_dag.py', '--cfg-path', '/tmp/tmp1_yaezmx', '--error-file', '/tmp/tmp2gegqt6d']
[2022-09-20 15:19:00,649] {standard_task_runner.py:77} INFO - Job 56: Subtask local_to_gcs_task
[2022-09-20 15:19:00,731] {logging_mixin.py:109} INFO - Running <TaskInstance: fhv_data_v2.local_to_gcs_task scheduled__2019-04-02T06:00:00+00:00 [running]> on host 0a2e8243e3d8
[2022-09-20 15:19:00,780] {warnings.py:110} WARNING - /home/***/.local/lib/python3.7/site-packages/***/utils/context.py:152: AirflowContextDeprecationWarning: Accessing 'execution_date' from the template is deprecated and will be removed in a future version. Please use 'data_interval_start' or 'logical_date' instead.
  warnings.warn(_create_deprecation_warning(key, self._deprecation_replacements[key]))

[2022-09-20 15:19:00,807] {taskinstance.py:1426} INFO - Exporting the following env vars:
AIRFLOW_CTX_DAG_OWNER=***
AIRFLOW_CTX_DAG_ID=fhv_data_v2
AIRFLOW_CTX_TASK_ID=local_to_gcs_task
AIRFLOW_CTX_EXECUTION_DATE=2019-04-02T06:00:00+00:00
AIRFLOW_CTX_DAG_RUN_ID=scheduled__2019-04-02T06:00:00+00:00
[2022-09-20 15:19:02,296] {taskinstance.py:1700} ERROR - Task failed with exception
Traceback (most recent call last):
  File "/home/airflow/.local/lib/python3.7/site-packages/google/cloud/storage/blob.py", line 2594, in upload_from_file
    retry=retry,
  File "/home/airflow/.local/lib/python3.7/site-packages/google/cloud/storage/blob.py", line 2412, in _do_upload
    retry=retry,
  File "/home/airflow/.local/lib/python3.7/site-packages/google/cloud/storage/blob.py", line 2237, in _do_resumable_upload
    retry=retry,
  File "/home/airflow/.local/lib/python3.7/site-packages/google/cloud/storage/blob.py", line 2112, in _initiate_resumable_upload
    timeout=timeout,
  File "/home/airflow/.local/lib/python3.7/site-packages/google/resumable_media/requests/upload.py", line 421, in initiate
    retriable_request, self._get_status_code, self._retry_strategy
  File "/home/airflow/.local/lib/python3.7/site-packages/google/resumable_media/requests/_request_helpers.py", line 147, in wait_and_retry
    response = func()
  File "/home/airflow/.local/lib/python3.7/site-packages/google/resumable_media/requests/upload.py", line 416, in retriable_request
    self._process_initiate_response(result)
  File "/home/airflow/.local/lib/python3.7/site-packages/google/resumable_media/_upload.py", line 503, in _process_initiate_response
    callback=self._make_invalid,
  File "/home/airflow/.local/lib/python3.7/site-packages/google/resumable_media/_helpers.py", line 104, in require_status_code
    *status_codes
google.resumable_media.common.InvalidResponse: ('Request failed with status code', 404, 'Expected one of', <HTTPStatus.OK: 200>, <HTTPStatus.CREATED: 201>)

During handling of the above exception, another exception occurred:

Traceback (most recent call last):
  File "/home/airflow/.local/lib/python3.7/site-packages/airflow/models/taskinstance.py", line 1329, in _run_raw_task
    self._execute_task_with_callbacks(context)
  File "/home/airflow/.local/lib/python3.7/site-packages/airflow/models/taskinstance.py", line 1455, in _execute_task_with_callbacks
    result = self._execute_task(context, self.task)
  File "/home/airflow/.local/lib/python3.7/site-packages/airflow/models/taskinstance.py", line 1511, in _execute_task
    result = execute_callable(context=context)
  File "/home/airflow/.local/lib/python3.7/site-packages/airflow/operators/python.py", line 174, in execute
    return_value = self.execute_callable()
  File "/home/airflow/.local/lib/python3.7/site-packages/airflow/operators/python.py", line 185, in execute_callable
    return self.python_callable(*self.op_args, **self.op_kwargs)
  File "/opt/airflow/dags/data_ingestion_gcs_dag.py", line 29, in upload_to_gcs
    blob.upload_from_filename(local_file)
  File "/home/airflow/.local/lib/python3.7/site-packages/google/cloud/storage/blob.py", line 2735, in upload_from_filename
    retry=retry,
  File "/home/airflow/.local/lib/python3.7/site-packages/google/cloud/storage/blob.py", line 2598, in upload_from_file
    _raise_from_invalid_response(exc)
  File "/home/airflow/.local/lib/python3.7/site-packages/google/cloud/storage/blob.py", line 4466, in _raise_from_invalid_response
    raise exceptions.from_http_status(response.status_code, message, response=response)
google.api_core.exceptions.NotFound: 404 POST https://storage.googleapis.com/upload/storage/v1/b/tez-bucket-new/o?uploadType=resumable: {
  "error": {
    "code": 404,
    "message": "The specified bucket does not exist.",
    "errors": [
      {
        "message": "The specified bucket does not exist.",
        "domain": "global",
        "reason": "notFound"
      }
    ]
  }
}
: ('Request failed with status code', 404, 'Expected one of', <HTTPStatus.OK: 200>, <HTTPStatus.CREATED: 201>)
[2022-09-20 15:19:02,312] {taskinstance.py:1277} INFO - Marking task as UP_FOR_RETRY. dag_id=fhv_data_v2, task_id=local_to_gcs_task, execution_date=20190402T060000, start_date=20220920T151900, end_date=20220920T151902
[2022-09-20 15:19:02,326] {standard_task_runner.py:92} ERROR - Failed to execute job 56 for task local_to_gcs_task
Traceback (most recent call last):
  File "/home/airflow/.local/lib/python3.7/site-packages/google/cloud/storage/blob.py", line 2594, in upload_from_file
    retry=retry,
  File "/home/airflow/.local/lib/python3.7/site-packages/google/cloud/storage/blob.py", line 2412, in _do_upload
    retry=retry,
  File "/home/airflow/.local/lib/python3.7/site-packages/google/cloud/storage/blob.py", line 2237, in _do_resumable_upload
    retry=retry,
  File "/home/airflow/.local/lib/python3.7/site-packages/google/cloud/storage/blob.py", line 2112, in _initiate_resumable_upload
    timeout=timeout,
  File "/home/airflow/.local/lib/python3.7/site-packages/google/resumable_media/requests/upload.py", line 421, in initiate
    retriable_request, self._get_status_code, self._retry_strategy
  File "/home/airflow/.local/lib/python3.7/site-packages/google/resumable_media/requests/_request_helpers.py", line 147, in wait_and_retry
    response = func()
  File "/home/airflow/.local/lib/python3.7/site-packages/google/resumable_media/requests/upload.py", line 416, in retriable_request
    self._process_initiate_response(result)
  File "/home/airflow/.local/lib/python3.7/site-packages/google/resumable_media/_upload.py", line 503, in _process_initiate_response
    callback=self._make_invalid,
  File "/home/airflow/.local/lib/python3.7/site-packages/google/resumable_media/_helpers.py", line 104, in require_status_code
    *status_codes
google.resumable_media.common.InvalidResponse: ('Request failed with status code', 404, 'Expected one of', <HTTPStatus.OK: 200>, <HTTPStatus.CREATED: 201>)

During handling of the above exception, another exception occurred:

Traceback (most recent call last):
  File "/home/airflow/.local/lib/python3.7/site-packages/airflow/task/task_runner/standard_task_runner.py", line 85, in _start_by_fork
    args.func(args, dag=self.dag)
  File "/home/airflow/.local/lib/python3.7/site-packages/airflow/cli/cli_parser.py", line 48, in command
    return func(*args, **kwargs)
  File "/home/airflow/.local/lib/python3.7/site-packages/airflow/utils/cli.py", line 92, in wrapper
    return f(*args, **kwargs)
  File "/home/airflow/.local/lib/python3.7/site-packages/airflow/cli/commands/task_command.py", line 298, in task_run
    _run_task_by_selected_method(args, dag, ti)
  File "/home/airflow/.local/lib/python3.7/site-packages/airflow/cli/commands/task_command.py", line 107, in _run_task_by_selected_method
    _run_raw_task(args, ti)
  File "/home/airflow/.local/lib/python3.7/site-packages/airflow/cli/commands/task_command.py", line 184, in _run_raw_task
    error_file=args.error_file,
  File "/home/airflow/.local/lib/python3.7/site-packages/airflow/utils/session.py", line 70, in wrapper
    return func(*args, session=session, **kwargs)
  File "/home/airflow/.local/lib/python3.7/site-packages/airflow/models/taskinstance.py", line 1329, in _run_raw_task
    self._execute_task_with_callbacks(context)
  File "/home/airflow/.local/lib/python3.7/site-packages/airflow/models/taskinstance.py", line 1455, in _execute_task_with_callbacks
    result = self._execute_task(context, self.task)
  File "/home/airflow/.local/lib/python3.7/site-packages/airflow/models/taskinstance.py", line 1511, in _execute_task
    result = execute_callable(context=context)
  File "/home/airflow/.local/lib/python3.7/site-packages/airflow/operators/python.py", line 174, in execute
    return_value = self.execute_callable()
  File "/home/airflow/.local/lib/python3.7/site-packages/airflow/operators/python.py", line 185, in execute_callable
    return self.python_callable(*self.op_args, **self.op_kwargs)
  File "/opt/airflow/dags/data_ingestion_gcs_dag.py", line 29, in upload_to_gcs
    blob.upload_from_filename(local_file)
  File "/home/airflow/.local/lib/python3.7/site-packages/google/cloud/storage/blob.py", line 2735, in upload_from_filename
    retry=retry,
  File "/home/airflow/.local/lib/python3.7/site-packages/google/cloud/storage/blob.py", line 2598, in upload_from_file
    _raise_from_invalid_response(exc)
  File "/home/airflow/.local/lib/python3.7/site-packages/google/cloud/storage/blob.py", line 4466, in _raise_from_invalid_response
    raise exceptions.from_http_status(response.status_code, message, response=response)
google.api_core.exceptions.NotFound: 404 POST https://storage.googleapis.com/upload/storage/v1/b/tez-bucket-new/o?uploadType=resumable: {
  "error": {
    "code": 404,
    "message": "The specified bucket does not exist.",
    "errors": [
      {
        "message": "The specified bucket does not exist.",
        "domain": "global",
        "reason": "notFound"
      }
    ]
  }
}
: ('Request failed with status code', 404, 'Expected one of', <HTTPStatus.OK: 200>, <HTTPStatus.CREATED: 201>)
[2022-09-20 15:19:02,351] {local_task_job.py:154} INFO - Task exited with return code 1
[2022-09-20 15:19:02,391] {local_task_job.py:264} INFO - 0 downstream tasks scheduled from follow-on schedule check
[2022-09-20 15:31:28,242] {taskinstance.py:1032} INFO - Dependencies all met for <TaskInstance: fhv_data_v2.local_to_gcs_task scheduled__2019-04-02T06:00:00+00:00 [queued]>
[2022-09-20 15:31:28,259] {taskinstance.py:1032} INFO - Dependencies all met for <TaskInstance: fhv_data_v2.local_to_gcs_task scheduled__2019-04-02T06:00:00+00:00 [queued]>
[2022-09-20 15:31:28,260] {taskinstance.py:1238} INFO - 
--------------------------------------------------------------------------------
[2022-09-20 15:31:28,260] {taskinstance.py:1239} INFO - Starting attempt 1 of 2
[2022-09-20 15:31:28,260] {taskinstance.py:1240} INFO - 
--------------------------------------------------------------------------------
[2022-09-20 15:31:28,279] {taskinstance.py:1259} INFO - Executing <Task(PythonOperator): local_to_gcs_task> on 2019-04-02 06:00:00+00:00
[2022-09-20 15:31:28,287] {standard_task_runner.py:52} INFO - Started process 179 to run task
[2022-09-20 15:31:28,293] {standard_task_runner.py:76} INFO - Running: ['***', 'tasks', 'run', 'fhv_data_v2', 'local_to_gcs_task', 'scheduled__2019-04-02T06:00:00+00:00', '--job-id', '13', '--raw', '--subdir', 'DAGS_FOLDER/data_ingestion_gcs_dag.py', '--cfg-path', '/tmp/tmp80ttzp4t', '--error-file', '/tmp/tmp_7sudzr5']
[2022-09-20 15:31:28,295] {standard_task_runner.py:77} INFO - Job 13: Subtask local_to_gcs_task
[2022-09-20 15:31:28,388] {logging_mixin.py:109} INFO - Running <TaskInstance: fhv_data_v2.local_to_gcs_task scheduled__2019-04-02T06:00:00+00:00 [running]> on host 788dccad41b9
[2022-09-20 15:31:28,450] {warnings.py:110} WARNING - /home/***/.local/lib/python3.7/site-packages/***/utils/context.py:152: AirflowContextDeprecationWarning: Accessing 'execution_date' from the template is deprecated and will be removed in a future version. Please use 'data_interval_start' or 'logical_date' instead.
  warnings.warn(_create_deprecation_warning(key, self._deprecation_replacements[key]))

[2022-09-20 15:31:28,482] {taskinstance.py:1426} INFO - Exporting the following env vars:
AIRFLOW_CTX_DAG_OWNER=***
AIRFLOW_CTX_DAG_ID=fhv_data_v2
AIRFLOW_CTX_TASK_ID=local_to_gcs_task
AIRFLOW_CTX_EXECUTION_DATE=2019-04-02T06:00:00+00:00
AIRFLOW_CTX_DAG_RUN_ID=scheduled__2019-04-02T06:00:00+00:00
[2022-09-20 15:31:29,160] {python.py:175} INFO - Done. Returned value was: None
[2022-09-20 15:31:29,179] {taskinstance.py:1277} INFO - Marking task as SUCCESS. dag_id=fhv_data_v2, task_id=local_to_gcs_task, execution_date=20190402T060000, start_date=20220920T153128, end_date=20220920T153129
[2022-09-20 15:31:29,245] {local_task_job.py:154} INFO - Task exited with return code 0
[2022-09-20 15:31:29,302] {local_task_job.py:264} INFO - 1 downstream tasks scheduled from follow-on schedule check
