[2022-09-17 06:52:21,875] {taskinstance.py:1032} INFO - Dependencies all met for <TaskInstance: fhv_data_v2.local_to_gcs_task scheduled__2019-06-02T06:00:00+00:00 [queued]>
[2022-09-17 06:52:21,887] {taskinstance.py:1032} INFO - Dependencies all met for <TaskInstance: fhv_data_v2.local_to_gcs_task scheduled__2019-06-02T06:00:00+00:00 [queued]>
[2022-09-17 06:52:21,887] {taskinstance.py:1238} INFO - 
--------------------------------------------------------------------------------
[2022-09-17 06:52:21,888] {taskinstance.py:1239} INFO - Starting attempt 1 of 2
[2022-09-17 06:52:21,888] {taskinstance.py:1240} INFO - 
--------------------------------------------------------------------------------
[2022-09-17 06:52:21,902] {taskinstance.py:1259} INFO - Executing <Task(PythonOperator): local_to_gcs_task> on 2019-06-02 06:00:00+00:00
[2022-09-17 06:52:21,909] {standard_task_runner.py:52} INFO - Started process 7429 to run task
[2022-09-17 06:52:21,915] {standard_task_runner.py:76} INFO - Running: ['***', 'tasks', 'run', 'fhv_data_v2', 'local_to_gcs_task', 'scheduled__2019-06-02T06:00:00+00:00', '--job-id', '96', '--raw', '--subdir', 'DAGS_FOLDER/data_ingestion_gcs_dag.py', '--cfg-path', '/tmp/tmpw0p8n_x7', '--error-file', '/tmp/tmp662fhksj']
[2022-09-17 06:52:21,916] {standard_task_runner.py:77} INFO - Job 96: Subtask local_to_gcs_task
[2022-09-17 06:52:22,004] {logging_mixin.py:109} INFO - Running <TaskInstance: fhv_data_v2.local_to_gcs_task scheduled__2019-06-02T06:00:00+00:00 [running]> on host 10d063af5ba7
[2022-09-17 06:52:22,068] {warnings.py:110} WARNING - /home/***/.local/lib/python3.7/site-packages/***/utils/context.py:152: AirflowContextDeprecationWarning: Accessing 'execution_date' from the template is deprecated and will be removed in a future version. Please use 'data_interval_start' or 'logical_date' instead.
  warnings.warn(_create_deprecation_warning(key, self._deprecation_replacements[key]))

[2022-09-17 06:52:22,103] {taskinstance.py:1426} INFO - Exporting the following env vars:
AIRFLOW_CTX_DAG_OWNER=***
AIRFLOW_CTX_DAG_ID=fhv_data_v2
AIRFLOW_CTX_TASK_ID=local_to_gcs_task
AIRFLOW_CTX_EXECUTION_DATE=2019-06-02T06:00:00+00:00
AIRFLOW_CTX_DAG_RUN_ID=scheduled__2019-06-02T06:00:00+00:00
[2022-09-17 06:52:23,902] {python.py:175} INFO - Done. Returned value was: None
[2022-09-17 06:52:23,918] {taskinstance.py:1277} INFO - Marking task as SUCCESS. dag_id=fhv_data_v2, task_id=local_to_gcs_task, execution_date=20190602T060000, start_date=20220917T065221, end_date=20220917T065223
[2022-09-17 06:52:23,940] {local_task_job.py:154} INFO - Task exited with return code 0
[2022-09-17 06:52:23,995] {local_task_job.py:264} INFO - 1 downstream tasks scheduled from follow-on schedule check
[2022-09-20 15:24:01,922] {taskinstance.py:1032} INFO - Dependencies all met for <TaskInstance: fhv_data_v2.local_to_gcs_task scheduled__2019-06-02T06:00:00+00:00 [queued]>
[2022-09-20 15:24:01,934] {taskinstance.py:1032} INFO - Dependencies all met for <TaskInstance: fhv_data_v2.local_to_gcs_task scheduled__2019-06-02T06:00:00+00:00 [queued]>
[2022-09-20 15:24:01,935] {taskinstance.py:1238} INFO - 
--------------------------------------------------------------------------------
[2022-09-20 15:24:01,935] {taskinstance.py:1239} INFO - Starting attempt 1 of 2
[2022-09-20 15:24:01,935] {taskinstance.py:1240} INFO - 
--------------------------------------------------------------------------------
[2022-09-20 15:24:01,950] {taskinstance.py:1259} INFO - Executing <Task(PythonOperator): local_to_gcs_task> on 2019-06-02 06:00:00+00:00
[2022-09-20 15:24:01,957] {standard_task_runner.py:52} INFO - Started process 735 to run task
[2022-09-20 15:24:01,962] {standard_task_runner.py:76} INFO - Running: ['***', 'tasks', 'run', 'fhv_data_v2', 'local_to_gcs_task', 'scheduled__2019-06-02T06:00:00+00:00', '--job-id', '60', '--raw', '--subdir', 'DAGS_FOLDER/data_ingestion_gcs_dag.py', '--cfg-path', '/tmp/tmpsyrj1xpb', '--error-file', '/tmp/tmpz26036n1']
[2022-09-20 15:24:01,963] {standard_task_runner.py:77} INFO - Job 60: Subtask local_to_gcs_task
[2022-09-20 15:24:02,026] {logging_mixin.py:109} INFO - Running <TaskInstance: fhv_data_v2.local_to_gcs_task scheduled__2019-06-02T06:00:00+00:00 [running]> on host 0a2e8243e3d8
[2022-09-20 15:24:02,070] {warnings.py:110} WARNING - /home/***/.local/lib/python3.7/site-packages/***/utils/context.py:152: AirflowContextDeprecationWarning: Accessing 'execution_date' from the template is deprecated and will be removed in a future version. Please use 'data_interval_start' or 'logical_date' instead.
  warnings.warn(_create_deprecation_warning(key, self._deprecation_replacements[key]))

[2022-09-20 15:24:02,094] {taskinstance.py:1426} INFO - Exporting the following env vars:
AIRFLOW_CTX_DAG_OWNER=***
AIRFLOW_CTX_DAG_ID=fhv_data_v2
AIRFLOW_CTX_TASK_ID=local_to_gcs_task
AIRFLOW_CTX_EXECUTION_DATE=2019-06-02T06:00:00+00:00
AIRFLOW_CTX_DAG_RUN_ID=scheduled__2019-06-02T06:00:00+00:00
[2022-09-20 15:24:03,226] {taskinstance.py:1700} ERROR - Task failed with exception
Traceback (most recent call last):
  File "/home/airflow/.local/lib/python3.7/site-packages/google/cloud/storage/blob.py", line 2594, in upload_from_file
    retry=retry,
  File "/home/airflow/.local/lib/python3.7/site-packages/google/cloud/storage/blob.py", line 2412, in _do_upload
    retry=retry,
  File "/home/airflow/.local/lib/python3.7/site-packages/google/cloud/storage/blob.py", line 2237, in _do_resumable_upload
    retry=retry,
  File "/home/airflow/.local/lib/python3.7/site-packages/google/cloud/storage/blob.py", line 2112, in _initiate_resumable_upload
    timeout=timeout,
  File "/home/airflow/.local/lib/python3.7/site-packages/google/resumable_media/requests/upload.py", line 421, in initiate
    retriable_request, self._get_status_code, self._retry_strategy
  File "/home/airflow/.local/lib/python3.7/site-packages/google/resumable_media/requests/_request_helpers.py", line 147, in wait_and_retry
    response = func()
  File "/home/airflow/.local/lib/python3.7/site-packages/google/resumable_media/requests/upload.py", line 416, in retriable_request
    self._process_initiate_response(result)
  File "/home/airflow/.local/lib/python3.7/site-packages/google/resumable_media/_upload.py", line 503, in _process_initiate_response
    callback=self._make_invalid,
  File "/home/airflow/.local/lib/python3.7/site-packages/google/resumable_media/_helpers.py", line 104, in require_status_code
    *status_codes
google.resumable_media.common.InvalidResponse: ('Request failed with status code', 404, 'Expected one of', <HTTPStatus.OK: 200>, <HTTPStatus.CREATED: 201>)

During handling of the above exception, another exception occurred:

Traceback (most recent call last):
  File "/home/airflow/.local/lib/python3.7/site-packages/airflow/models/taskinstance.py", line 1329, in _run_raw_task
    self._execute_task_with_callbacks(context)
  File "/home/airflow/.local/lib/python3.7/site-packages/airflow/models/taskinstance.py", line 1455, in _execute_task_with_callbacks
    result = self._execute_task(context, self.task)
  File "/home/airflow/.local/lib/python3.7/site-packages/airflow/models/taskinstance.py", line 1511, in _execute_task
    result = execute_callable(context=context)
  File "/home/airflow/.local/lib/python3.7/site-packages/airflow/operators/python.py", line 174, in execute
    return_value = self.execute_callable()
  File "/home/airflow/.local/lib/python3.7/site-packages/airflow/operators/python.py", line 185, in execute_callable
    return self.python_callable(*self.op_args, **self.op_kwargs)
  File "/opt/airflow/dags/data_ingestion_gcs_dag.py", line 29, in upload_to_gcs
    blob.upload_from_filename(local_file)
  File "/home/airflow/.local/lib/python3.7/site-packages/google/cloud/storage/blob.py", line 2735, in upload_from_filename
    retry=retry,
  File "/home/airflow/.local/lib/python3.7/site-packages/google/cloud/storage/blob.py", line 2598, in upload_from_file
    _raise_from_invalid_response(exc)
  File "/home/airflow/.local/lib/python3.7/site-packages/google/cloud/storage/blob.py", line 4466, in _raise_from_invalid_response
    raise exceptions.from_http_status(response.status_code, message, response=response)
google.api_core.exceptions.NotFound: 404 POST https://storage.googleapis.com/upload/storage/v1/b/tez-bucket-new/o?uploadType=resumable: {
  "error": {
    "code": 404,
    "message": "The specified bucket does not exist.",
    "errors": [
      {
        "message": "The specified bucket does not exist.",
        "domain": "global",
        "reason": "notFound"
      }
    ]
  }
}
: ('Request failed with status code', 404, 'Expected one of', <HTTPStatus.OK: 200>, <HTTPStatus.CREATED: 201>)
[2022-09-20 15:24:03,252] {taskinstance.py:1277} INFO - Marking task as UP_FOR_RETRY. dag_id=fhv_data_v2, task_id=local_to_gcs_task, execution_date=20190602T060000, start_date=20220920T152401, end_date=20220920T152403
[2022-09-20 15:24:03,272] {standard_task_runner.py:92} ERROR - Failed to execute job 60 for task local_to_gcs_task
Traceback (most recent call last):
  File "/home/airflow/.local/lib/python3.7/site-packages/google/cloud/storage/blob.py", line 2594, in upload_from_file
    retry=retry,
  File "/home/airflow/.local/lib/python3.7/site-packages/google/cloud/storage/blob.py", line 2412, in _do_upload
    retry=retry,
  File "/home/airflow/.local/lib/python3.7/site-packages/google/cloud/storage/blob.py", line 2237, in _do_resumable_upload
    retry=retry,
  File "/home/airflow/.local/lib/python3.7/site-packages/google/cloud/storage/blob.py", line 2112, in _initiate_resumable_upload
    timeout=timeout,
  File "/home/airflow/.local/lib/python3.7/site-packages/google/resumable_media/requests/upload.py", line 421, in initiate
    retriable_request, self._get_status_code, self._retry_strategy
  File "/home/airflow/.local/lib/python3.7/site-packages/google/resumable_media/requests/_request_helpers.py", line 147, in wait_and_retry
    response = func()
  File "/home/airflow/.local/lib/python3.7/site-packages/google/resumable_media/requests/upload.py", line 416, in retriable_request
    self._process_initiate_response(result)
  File "/home/airflow/.local/lib/python3.7/site-packages/google/resumable_media/_upload.py", line 503, in _process_initiate_response
    callback=self._make_invalid,
  File "/home/airflow/.local/lib/python3.7/site-packages/google/resumable_media/_helpers.py", line 104, in require_status_code
    *status_codes
google.resumable_media.common.InvalidResponse: ('Request failed with status code', 404, 'Expected one of', <HTTPStatus.OK: 200>, <HTTPStatus.CREATED: 201>)

During handling of the above exception, another exception occurred:

Traceback (most recent call last):
  File "/home/airflow/.local/lib/python3.7/site-packages/airflow/task/task_runner/standard_task_runner.py", line 85, in _start_by_fork
    args.func(args, dag=self.dag)
  File "/home/airflow/.local/lib/python3.7/site-packages/airflow/cli/cli_parser.py", line 48, in command
    return func(*args, **kwargs)
  File "/home/airflow/.local/lib/python3.7/site-packages/airflow/utils/cli.py", line 92, in wrapper
    return f(*args, **kwargs)
  File "/home/airflow/.local/lib/python3.7/site-packages/airflow/cli/commands/task_command.py", line 298, in task_run
    _run_task_by_selected_method(args, dag, ti)
  File "/home/airflow/.local/lib/python3.7/site-packages/airflow/cli/commands/task_command.py", line 107, in _run_task_by_selected_method
    _run_raw_task(args, ti)
  File "/home/airflow/.local/lib/python3.7/site-packages/airflow/cli/commands/task_command.py", line 184, in _run_raw_task
    error_file=args.error_file,
  File "/home/airflow/.local/lib/python3.7/site-packages/airflow/utils/session.py", line 70, in wrapper
    return func(*args, session=session, **kwargs)
  File "/home/airflow/.local/lib/python3.7/site-packages/airflow/models/taskinstance.py", line 1329, in _run_raw_task
    self._execute_task_with_callbacks(context)
  File "/home/airflow/.local/lib/python3.7/site-packages/airflow/models/taskinstance.py", line 1455, in _execute_task_with_callbacks
    result = self._execute_task(context, self.task)
  File "/home/airflow/.local/lib/python3.7/site-packages/airflow/models/taskinstance.py", line 1511, in _execute_task
    result = execute_callable(context=context)
  File "/home/airflow/.local/lib/python3.7/site-packages/airflow/operators/python.py", line 174, in execute
    return_value = self.execute_callable()
  File "/home/airflow/.local/lib/python3.7/site-packages/airflow/operators/python.py", line 185, in execute_callable
    return self.python_callable(*self.op_args, **self.op_kwargs)
  File "/opt/airflow/dags/data_ingestion_gcs_dag.py", line 29, in upload_to_gcs
    blob.upload_from_filename(local_file)
  File "/home/airflow/.local/lib/python3.7/site-packages/google/cloud/storage/blob.py", line 2735, in upload_from_filename
    retry=retry,
  File "/home/airflow/.local/lib/python3.7/site-packages/google/cloud/storage/blob.py", line 2598, in upload_from_file
    _raise_from_invalid_response(exc)
  File "/home/airflow/.local/lib/python3.7/site-packages/google/cloud/storage/blob.py", line 4466, in _raise_from_invalid_response
    raise exceptions.from_http_status(response.status_code, message, response=response)
google.api_core.exceptions.NotFound: 404 POST https://storage.googleapis.com/upload/storage/v1/b/tez-bucket-new/o?uploadType=resumable: {
  "error": {
    "code": 404,
    "message": "The specified bucket does not exist.",
    "errors": [
      {
        "message": "The specified bucket does not exist.",
        "domain": "global",
        "reason": "notFound"
      }
    ]
  }
}
: ('Request failed with status code', 404, 'Expected one of', <HTTPStatus.OK: 200>, <HTTPStatus.CREATED: 201>)
[2022-09-20 15:24:03,298] {local_task_job.py:154} INFO - Task exited with return code 1
[2022-09-20 15:24:03,369] {local_task_job.py:264} INFO - 0 downstream tasks scheduled from follow-on schedule check
[2022-09-20 15:31:43,287] {taskinstance.py:1032} INFO - Dependencies all met for <TaskInstance: fhv_data_v2.local_to_gcs_task scheduled__2019-06-02T06:00:00+00:00 [queued]>
[2022-09-20 15:31:43,318] {taskinstance.py:1032} INFO - Dependencies all met for <TaskInstance: fhv_data_v2.local_to_gcs_task scheduled__2019-06-02T06:00:00+00:00 [queued]>
[2022-09-20 15:31:43,319] {taskinstance.py:1238} INFO - 
--------------------------------------------------------------------------------
[2022-09-20 15:31:43,319] {taskinstance.py:1239} INFO - Starting attempt 1 of 2
[2022-09-20 15:31:43,319] {taskinstance.py:1240} INFO - 
--------------------------------------------------------------------------------
[2022-09-20 15:31:43,348] {taskinstance.py:1259} INFO - Executing <Task(PythonOperator): local_to_gcs_task> on 2019-06-02 06:00:00+00:00
[2022-09-20 15:31:43,356] {standard_task_runner.py:52} INFO - Started process 265 to run task
[2022-09-20 15:31:43,380] {standard_task_runner.py:76} INFO - Running: ['***', 'tasks', 'run', 'fhv_data_v2', 'local_to_gcs_task', 'scheduled__2019-06-02T06:00:00+00:00', '--job-id', '29', '--raw', '--subdir', 'DAGS_FOLDER/data_ingestion_gcs_dag.py', '--cfg-path', '/tmp/tmpcdrjo7l7', '--error-file', '/tmp/tmpy4lik19k']
[2022-09-20 15:31:43,384] {standard_task_runner.py:77} INFO - Job 29: Subtask local_to_gcs_task
[2022-09-20 15:31:43,693] {logging_mixin.py:109} INFO - Running <TaskInstance: fhv_data_v2.local_to_gcs_task scheduled__2019-06-02T06:00:00+00:00 [running]> on host 788dccad41b9
[2022-09-20 15:31:43,919] {warnings.py:110} WARNING - /home/***/.local/lib/python3.7/site-packages/***/utils/context.py:152: AirflowContextDeprecationWarning: Accessing 'execution_date' from the template is deprecated and will be removed in a future version. Please use 'data_interval_start' or 'logical_date' instead.
  warnings.warn(_create_deprecation_warning(key, self._deprecation_replacements[key]))

[2022-09-20 15:31:43,988] {taskinstance.py:1426} INFO - Exporting the following env vars:
AIRFLOW_CTX_DAG_OWNER=***
AIRFLOW_CTX_DAG_ID=fhv_data_v2
AIRFLOW_CTX_TASK_ID=local_to_gcs_task
AIRFLOW_CTX_EXECUTION_DATE=2019-06-02T06:00:00+00:00
AIRFLOW_CTX_DAG_RUN_ID=scheduled__2019-06-02T06:00:00+00:00
[2022-09-20 15:31:44,707] {python.py:175} INFO - Done. Returned value was: None
[2022-09-20 15:31:44,780] {taskinstance.py:1277} INFO - Marking task as SUCCESS. dag_id=fhv_data_v2, task_id=local_to_gcs_task, execution_date=20190602T060000, start_date=20220920T153143, end_date=20220920T153144
[2022-09-20 15:31:44,954] {local_task_job.py:154} INFO - Task exited with return code 0
[2022-09-20 15:31:45,174] {local_task_job.py:264} INFO - 1 downstream tasks scheduled from follow-on schedule check
