[2022-09-17 06:52:33,703] {taskinstance.py:1032} INFO - Dependencies all met for <TaskInstance: fhv_data_v2.local_to_gcs_task scheduled__2019-08-02T06:00:00+00:00 [queued]>
[2022-09-17 06:52:33,719] {taskinstance.py:1032} INFO - Dependencies all met for <TaskInstance: fhv_data_v2.local_to_gcs_task scheduled__2019-08-02T06:00:00+00:00 [queued]>
[2022-09-17 06:52:33,719] {taskinstance.py:1238} INFO - 
--------------------------------------------------------------------------------
[2022-09-17 06:52:33,719] {taskinstance.py:1239} INFO - Starting attempt 1 of 2
[2022-09-17 06:52:33,719] {taskinstance.py:1240} INFO - 
--------------------------------------------------------------------------------
[2022-09-17 06:52:33,741] {taskinstance.py:1259} INFO - Executing <Task(PythonOperator): local_to_gcs_task> on 2019-08-02 06:00:00+00:00
[2022-09-17 06:52:33,748] {standard_task_runner.py:52} INFO - Started process 7466 to run task
[2022-09-17 06:52:33,754] {standard_task_runner.py:76} INFO - Running: ['***', 'tasks', 'run', 'fhv_data_v2', 'local_to_gcs_task', 'scheduled__2019-08-02T06:00:00+00:00', '--job-id', '104', '--raw', '--subdir', 'DAGS_FOLDER/data_ingestion_gcs_dag.py', '--cfg-path', '/tmp/tmpy7k3_ju6', '--error-file', '/tmp/tmp7wb9axq0']
[2022-09-17 06:52:33,756] {standard_task_runner.py:77} INFO - Job 104: Subtask local_to_gcs_task
[2022-09-17 06:52:33,832] {logging_mixin.py:109} INFO - Running <TaskInstance: fhv_data_v2.local_to_gcs_task scheduled__2019-08-02T06:00:00+00:00 [running]> on host 10d063af5ba7
[2022-09-17 06:52:33,881] {warnings.py:110} WARNING - /home/***/.local/lib/python3.7/site-packages/***/utils/context.py:152: AirflowContextDeprecationWarning: Accessing 'execution_date' from the template is deprecated and will be removed in a future version. Please use 'data_interval_start' or 'logical_date' instead.
  warnings.warn(_create_deprecation_warning(key, self._deprecation_replacements[key]))

[2022-09-17 06:52:33,905] {taskinstance.py:1426} INFO - Exporting the following env vars:
AIRFLOW_CTX_DAG_OWNER=***
AIRFLOW_CTX_DAG_ID=fhv_data_v2
AIRFLOW_CTX_TASK_ID=local_to_gcs_task
AIRFLOW_CTX_EXECUTION_DATE=2019-08-02T06:00:00+00:00
AIRFLOW_CTX_DAG_RUN_ID=scheduled__2019-08-02T06:00:00+00:00
[2022-09-17 06:52:35,379] {python.py:175} INFO - Done. Returned value was: None
[2022-09-17 06:52:35,393] {taskinstance.py:1277} INFO - Marking task as SUCCESS. dag_id=fhv_data_v2, task_id=local_to_gcs_task, execution_date=20190802T060000, start_date=20220917T065233, end_date=20220917T065235
[2022-09-17 06:52:35,454] {local_task_job.py:154} INFO - Task exited with return code 0
[2022-09-17 06:52:35,500] {local_task_job.py:264} INFO - 1 downstream tasks scheduled from follow-on schedule check
[2022-09-20 15:24:15,271] {taskinstance.py:1032} INFO - Dependencies all met for <TaskInstance: fhv_data_v2.local_to_gcs_task scheduled__2019-08-02T06:00:00+00:00 [queued]>
[2022-09-20 15:24:15,287] {taskinstance.py:1032} INFO - Dependencies all met for <TaskInstance: fhv_data_v2.local_to_gcs_task scheduled__2019-08-02T06:00:00+00:00 [queued]>
[2022-09-20 15:24:15,287] {taskinstance.py:1238} INFO - 
--------------------------------------------------------------------------------
[2022-09-20 15:24:15,287] {taskinstance.py:1239} INFO - Starting attempt 1 of 2
[2022-09-20 15:24:15,287] {taskinstance.py:1240} INFO - 
--------------------------------------------------------------------------------
[2022-09-20 15:24:15,303] {taskinstance.py:1259} INFO - Executing <Task(PythonOperator): local_to_gcs_task> on 2019-08-02 06:00:00+00:00
[2022-09-20 15:24:15,310] {standard_task_runner.py:52} INFO - Started process 768 to run task
[2022-09-20 15:24:15,315] {standard_task_runner.py:76} INFO - Running: ['***', 'tasks', 'run', 'fhv_data_v2', 'local_to_gcs_task', 'scheduled__2019-08-02T06:00:00+00:00', '--job-id', '66', '--raw', '--subdir', 'DAGS_FOLDER/data_ingestion_gcs_dag.py', '--cfg-path', '/tmp/tmpkdoksmd5', '--error-file', '/tmp/tmprmbgtnpq']
[2022-09-20 15:24:15,316] {standard_task_runner.py:77} INFO - Job 66: Subtask local_to_gcs_task
[2022-09-20 15:24:15,376] {logging_mixin.py:109} INFO - Running <TaskInstance: fhv_data_v2.local_to_gcs_task scheduled__2019-08-02T06:00:00+00:00 [running]> on host 0a2e8243e3d8
[2022-09-20 15:24:15,416] {warnings.py:110} WARNING - /home/***/.local/lib/python3.7/site-packages/***/utils/context.py:152: AirflowContextDeprecationWarning: Accessing 'execution_date' from the template is deprecated and will be removed in a future version. Please use 'data_interval_start' or 'logical_date' instead.
  warnings.warn(_create_deprecation_warning(key, self._deprecation_replacements[key]))

[2022-09-20 15:24:15,443] {taskinstance.py:1426} INFO - Exporting the following env vars:
AIRFLOW_CTX_DAG_OWNER=***
AIRFLOW_CTX_DAG_ID=fhv_data_v2
AIRFLOW_CTX_TASK_ID=local_to_gcs_task
AIRFLOW_CTX_EXECUTION_DATE=2019-08-02T06:00:00+00:00
AIRFLOW_CTX_DAG_RUN_ID=scheduled__2019-08-02T06:00:00+00:00
[2022-09-20 15:24:16,755] {taskinstance.py:1700} ERROR - Task failed with exception
Traceback (most recent call last):
  File "/home/airflow/.local/lib/python3.7/site-packages/google/cloud/storage/blob.py", line 2594, in upload_from_file
    retry=retry,
  File "/home/airflow/.local/lib/python3.7/site-packages/google/cloud/storage/blob.py", line 2412, in _do_upload
    retry=retry,
  File "/home/airflow/.local/lib/python3.7/site-packages/google/cloud/storage/blob.py", line 2237, in _do_resumable_upload
    retry=retry,
  File "/home/airflow/.local/lib/python3.7/site-packages/google/cloud/storage/blob.py", line 2112, in _initiate_resumable_upload
    timeout=timeout,
  File "/home/airflow/.local/lib/python3.7/site-packages/google/resumable_media/requests/upload.py", line 421, in initiate
    retriable_request, self._get_status_code, self._retry_strategy
  File "/home/airflow/.local/lib/python3.7/site-packages/google/resumable_media/requests/_request_helpers.py", line 147, in wait_and_retry
    response = func()
  File "/home/airflow/.local/lib/python3.7/site-packages/google/resumable_media/requests/upload.py", line 416, in retriable_request
    self._process_initiate_response(result)
  File "/home/airflow/.local/lib/python3.7/site-packages/google/resumable_media/_upload.py", line 503, in _process_initiate_response
    callback=self._make_invalid,
  File "/home/airflow/.local/lib/python3.7/site-packages/google/resumable_media/_helpers.py", line 104, in require_status_code
    *status_codes
google.resumable_media.common.InvalidResponse: ('Request failed with status code', 404, 'Expected one of', <HTTPStatus.OK: 200>, <HTTPStatus.CREATED: 201>)

During handling of the above exception, another exception occurred:

Traceback (most recent call last):
  File "/home/airflow/.local/lib/python3.7/site-packages/airflow/models/taskinstance.py", line 1329, in _run_raw_task
    self._execute_task_with_callbacks(context)
  File "/home/airflow/.local/lib/python3.7/site-packages/airflow/models/taskinstance.py", line 1455, in _execute_task_with_callbacks
    result = self._execute_task(context, self.task)
  File "/home/airflow/.local/lib/python3.7/site-packages/airflow/models/taskinstance.py", line 1511, in _execute_task
    result = execute_callable(context=context)
  File "/home/airflow/.local/lib/python3.7/site-packages/airflow/operators/python.py", line 174, in execute
    return_value = self.execute_callable()
  File "/home/airflow/.local/lib/python3.7/site-packages/airflow/operators/python.py", line 185, in execute_callable
    return self.python_callable(*self.op_args, **self.op_kwargs)
  File "/opt/airflow/dags/data_ingestion_gcs_dag.py", line 29, in upload_to_gcs
    blob.upload_from_filename(local_file)
  File "/home/airflow/.local/lib/python3.7/site-packages/google/cloud/storage/blob.py", line 2735, in upload_from_filename
    retry=retry,
  File "/home/airflow/.local/lib/python3.7/site-packages/google/cloud/storage/blob.py", line 2598, in upload_from_file
    _raise_from_invalid_response(exc)
  File "/home/airflow/.local/lib/python3.7/site-packages/google/cloud/storage/blob.py", line 4466, in _raise_from_invalid_response
    raise exceptions.from_http_status(response.status_code, message, response=response)
google.api_core.exceptions.NotFound: 404 POST https://storage.googleapis.com/upload/storage/v1/b/tez-bucket-new/o?uploadType=resumable: {
  "error": {
    "code": 404,
    "message": "The specified bucket does not exist.",
    "errors": [
      {
        "message": "The specified bucket does not exist.",
        "domain": "global",
        "reason": "notFound"
      }
    ]
  }
}
: ('Request failed with status code', 404, 'Expected one of', <HTTPStatus.OK: 200>, <HTTPStatus.CREATED: 201>)
[2022-09-20 15:24:16,779] {taskinstance.py:1277} INFO - Marking task as UP_FOR_RETRY. dag_id=fhv_data_v2, task_id=local_to_gcs_task, execution_date=20190802T060000, start_date=20220920T152415, end_date=20220920T152416
[2022-09-20 15:24:16,821] {standard_task_runner.py:92} ERROR - Failed to execute job 66 for task local_to_gcs_task
Traceback (most recent call last):
  File "/home/airflow/.local/lib/python3.7/site-packages/google/cloud/storage/blob.py", line 2594, in upload_from_file
    retry=retry,
  File "/home/airflow/.local/lib/python3.7/site-packages/google/cloud/storage/blob.py", line 2412, in _do_upload
    retry=retry,
  File "/home/airflow/.local/lib/python3.7/site-packages/google/cloud/storage/blob.py", line 2237, in _do_resumable_upload
    retry=retry,
  File "/home/airflow/.local/lib/python3.7/site-packages/google/cloud/storage/blob.py", line 2112, in _initiate_resumable_upload
    timeout=timeout,
  File "/home/airflow/.local/lib/python3.7/site-packages/google/resumable_media/requests/upload.py", line 421, in initiate
    retriable_request, self._get_status_code, self._retry_strategy
  File "/home/airflow/.local/lib/python3.7/site-packages/google/resumable_media/requests/_request_helpers.py", line 147, in wait_and_retry
    response = func()
  File "/home/airflow/.local/lib/python3.7/site-packages/google/resumable_media/requests/upload.py", line 416, in retriable_request
    self._process_initiate_response(result)
  File "/home/airflow/.local/lib/python3.7/site-packages/google/resumable_media/_upload.py", line 503, in _process_initiate_response
    callback=self._make_invalid,
  File "/home/airflow/.local/lib/python3.7/site-packages/google/resumable_media/_helpers.py", line 104, in require_status_code
    *status_codes
google.resumable_media.common.InvalidResponse: ('Request failed with status code', 404, 'Expected one of', <HTTPStatus.OK: 200>, <HTTPStatus.CREATED: 201>)

During handling of the above exception, another exception occurred:

Traceback (most recent call last):
  File "/home/airflow/.local/lib/python3.7/site-packages/airflow/task/task_runner/standard_task_runner.py", line 85, in _start_by_fork
    args.func(args, dag=self.dag)
  File "/home/airflow/.local/lib/python3.7/site-packages/airflow/cli/cli_parser.py", line 48, in command
    return func(*args, **kwargs)
  File "/home/airflow/.local/lib/python3.7/site-packages/airflow/utils/cli.py", line 92, in wrapper
    return f(*args, **kwargs)
  File "/home/airflow/.local/lib/python3.7/site-packages/airflow/cli/commands/task_command.py", line 298, in task_run
    _run_task_by_selected_method(args, dag, ti)
  File "/home/airflow/.local/lib/python3.7/site-packages/airflow/cli/commands/task_command.py", line 107, in _run_task_by_selected_method
    _run_raw_task(args, ti)
  File "/home/airflow/.local/lib/python3.7/site-packages/airflow/cli/commands/task_command.py", line 184, in _run_raw_task
    error_file=args.error_file,
  File "/home/airflow/.local/lib/python3.7/site-packages/airflow/utils/session.py", line 70, in wrapper
    return func(*args, session=session, **kwargs)
  File "/home/airflow/.local/lib/python3.7/site-packages/airflow/models/taskinstance.py", line 1329, in _run_raw_task
    self._execute_task_with_callbacks(context)
  File "/home/airflow/.local/lib/python3.7/site-packages/airflow/models/taskinstance.py", line 1455, in _execute_task_with_callbacks
    result = self._execute_task(context, self.task)
  File "/home/airflow/.local/lib/python3.7/site-packages/airflow/models/taskinstance.py", line 1511, in _execute_task
    result = execute_callable(context=context)
  File "/home/airflow/.local/lib/python3.7/site-packages/airflow/operators/python.py", line 174, in execute
    return_value = self.execute_callable()
  File "/home/airflow/.local/lib/python3.7/site-packages/airflow/operators/python.py", line 185, in execute_callable
    return self.python_callable(*self.op_args, **self.op_kwargs)
  File "/opt/airflow/dags/data_ingestion_gcs_dag.py", line 29, in upload_to_gcs
    blob.upload_from_filename(local_file)
  File "/home/airflow/.local/lib/python3.7/site-packages/google/cloud/storage/blob.py", line 2735, in upload_from_filename
    retry=retry,
  File "/home/airflow/.local/lib/python3.7/site-packages/google/cloud/storage/blob.py", line 2598, in upload_from_file
    _raise_from_invalid_response(exc)
  File "/home/airflow/.local/lib/python3.7/site-packages/google/cloud/storage/blob.py", line 4466, in _raise_from_invalid_response
    raise exceptions.from_http_status(response.status_code, message, response=response)
google.api_core.exceptions.NotFound: 404 POST https://storage.googleapis.com/upload/storage/v1/b/tez-bucket-new/o?uploadType=resumable: {
  "error": {
    "code": 404,
    "message": "The specified bucket does not exist.",
    "errors": [
      {
        "message": "The specified bucket does not exist.",
        "domain": "global",
        "reason": "notFound"
      }
    ]
  }
}
: ('Request failed with status code', 404, 'Expected one of', <HTTPStatus.OK: 200>, <HTTPStatus.CREATED: 201>)
[2022-09-20 15:24:16,851] {local_task_job.py:154} INFO - Task exited with return code 1
[2022-09-20 15:24:16,900] {local_task_job.py:264} INFO - 0 downstream tasks scheduled from follow-on schedule check
[2022-09-20 15:31:57,789] {taskinstance.py:1032} INFO - Dependencies all met for <TaskInstance: fhv_data_v2.local_to_gcs_task scheduled__2019-08-02T06:00:00+00:00 [queued]>
[2022-09-20 15:31:57,804] {taskinstance.py:1032} INFO - Dependencies all met for <TaskInstance: fhv_data_v2.local_to_gcs_task scheduled__2019-08-02T06:00:00+00:00 [queued]>
[2022-09-20 15:31:57,804] {taskinstance.py:1238} INFO - 
--------------------------------------------------------------------------------
[2022-09-20 15:31:57,804] {taskinstance.py:1239} INFO - Starting attempt 1 of 2
[2022-09-20 15:31:57,804] {taskinstance.py:1240} INFO - 
--------------------------------------------------------------------------------
[2022-09-20 15:31:57,826] {taskinstance.py:1259} INFO - Executing <Task(PythonOperator): local_to_gcs_task> on 2019-08-02 06:00:00+00:00
[2022-09-20 15:31:57,834] {standard_task_runner.py:52} INFO - Started process 334 to run task
[2022-09-20 15:31:57,851] {standard_task_runner.py:76} INFO - Running: ['***', 'tasks', 'run', 'fhv_data_v2', 'local_to_gcs_task', 'scheduled__2019-08-02T06:00:00+00:00', '--job-id', '47', '--raw', '--subdir', 'DAGS_FOLDER/data_ingestion_gcs_dag.py', '--cfg-path', '/tmp/tmp75d_gxwp', '--error-file', '/tmp/tmp_djw4xgh']
[2022-09-20 15:31:57,852] {standard_task_runner.py:77} INFO - Job 47: Subtask local_to_gcs_task
[2022-09-20 15:31:57,954] {logging_mixin.py:109} INFO - Running <TaskInstance: fhv_data_v2.local_to_gcs_task scheduled__2019-08-02T06:00:00+00:00 [running]> on host 788dccad41b9
[2022-09-20 15:31:58,028] {warnings.py:110} WARNING - /home/***/.local/lib/python3.7/site-packages/***/utils/context.py:152: AirflowContextDeprecationWarning: Accessing 'execution_date' from the template is deprecated and will be removed in a future version. Please use 'data_interval_start' or 'logical_date' instead.
  warnings.warn(_create_deprecation_warning(key, self._deprecation_replacements[key]))

[2022-09-20 15:31:58,080] {taskinstance.py:1426} INFO - Exporting the following env vars:
AIRFLOW_CTX_DAG_OWNER=***
AIRFLOW_CTX_DAG_ID=fhv_data_v2
AIRFLOW_CTX_TASK_ID=local_to_gcs_task
AIRFLOW_CTX_EXECUTION_DATE=2019-08-02T06:00:00+00:00
AIRFLOW_CTX_DAG_RUN_ID=scheduled__2019-08-02T06:00:00+00:00
[2022-09-20 15:31:59,047] {python.py:175} INFO - Done. Returned value was: None
[2022-09-20 15:31:59,069] {taskinstance.py:1277} INFO - Marking task as SUCCESS. dag_id=fhv_data_v2, task_id=local_to_gcs_task, execution_date=20190802T060000, start_date=20220920T153157, end_date=20220920T153159
[2022-09-20 15:31:59,154] {local_task_job.py:154} INFO - Task exited with return code 0
[2022-09-20 15:31:59,243] {local_task_job.py:264} INFO - 1 downstream tasks scheduled from follow-on schedule check
